Workbook

Sheet Zusammenfassung_Volumenströme
A1: Berechnung Volumenströme
A3: Volumenstrom Badebetrieb | B3: =Volumenstrom_Badebetrieb!C67 -> 72.10237 | C3: m3/h
A4: Volumenstrom Ruhebetrieb | B4: =Volumenstrom_Ruhebetrieb!C38 -> 100.30247 | C4: m3/h
A5: Min Volumenstrom Fenster | B5: =Min_Volumenstrom_für_Fenster!C8 -> 1187.5 | C5: m3/h
A7: Volumenstrom Wärmebedarf | B7: =Volumenstrom_über_Wärmeanfall!C41 -> 1580.347 | C7: m3/h
A8: Volumenstrom min Frischluft (Personen) | B8: =Volumenstrom_nach_Personenbeleg!C14 -> 600 | C8: m3/h | D8: mind. einzuhalten

Sheet Volumenstrom_Badebetrieb
A1: Berechnungen Badebetrieb
A3: Berechnung Luftdruck
A5: geg | B5: Normdruck | C5: 1013.25 | D5: mbar
B6: Meereshöhe | C6: 0.4 | D6: km
A8: ges | B8: Luftdruck bei Meereshöhe | C8: =C5*((1-(6.5/288))*C6)^5.256 -> 7.2783926
A11: Berechnug Sättigungsdruck Wasser
A13: geg | B13: Sättigunstemperatur | C13: 32 | D13: °C
A15: ges | B15: Sättigungsdruck | C15: =288.86*(1.098+(C13/100))^8.02 -> 4754.7838 | D15: Pa
A17: Umrechnung Pascal in Millibar
A19: geg | B19: Sätigungsdruck | C19: =C15 -> 4754.7838 | D19: Pa
B21: Sättigungsdruck | C21: =C19/100 -> 47.547838 | D21: mbar
A23: Berechnung Partialdruck
A25: geg | B25: Barometerdruck | C25: 962 | D25: mbar
B26: Feuchte Raum SOLL | C26: 14.3 | D26: g/kg
A28: ges | B28: Partialdruck | C28: =(C25*(C26/1000))/(0.622+(C26/1000)) -> 21.619676 | D28: mbar
A31: Wasserdampanfall Schwimmbad
A33: geg | B33: Verdunstungswert ε | C33: 4 | D33: g/m3*h*mbar
B34: Fläche | C34: 5 | D34: m2
B35: Wasserdampfsättigungsdruck | C35: =C21 -> 47.547838 | D35: mbar
B36: Wasserdampfdruck | C36: 21.63 | D36: mbar
A38: ges | B38: Wasserdampfanfall | C38: =C33*C34*(C35-C36) -> 518.35677 | D38: g/h
B39: Rinnenfaktor | C39: 0.8
B41: Wasserdampfanfall Total | C41: =SUM(C38*C39) -> 414.68541 | D41: g/h
A43: Wasserdampanfall Whirlpool
A45: geg | B45: Verdunstungswert | C45: 1050 | D45: g/h*m2
B46: Fläche | C46: 0 | D46: m2
A48: ges | B48: Wasserdampfanfall | C48: =C45*C46 -> 0 | D48: g/h
A50: Wasserdampf total | D50: g/h
C51: =C48+C41 -> 414.68541
A52: Dichteermittlung Luft
A54: geg | B54: Normdichte | C54: 1.293 | D54: kg/m3
B55: Temp | C55: 32 | D55: °C
B56: Druck | C56: 950 | D56: Pa
A58: ges | B58: Dichte | C58: =C54*(273.15/(273.15+C55))*(C56/1013.25) -> 1.0851589 | D58: kg/m3
A60: Volumenstrom über Wasserdampf
A62: geg | B62: Wasserdampfanfall | C62: =C51 -> 414.68541 | D62: g/h
B63: Feuchte Raum | C63: 14.3 | D63: g/kg
B64: Feuchte ZUL | C64: 9 | D64: g/kg
B65: Dichte Luft | C65: =C58 -> 1.0851589 | D65: kg/m3
A67: ges | B67: Volumenstrom über Dampfanfall | C67: =C62/((C63-C64)*C65) -> 72.10237 | D67: m3/h

Sheet Volumenstrom_Ruhebetrieb
A1: Berechnungen Ruhebetrieb
A3: Wasserdampanfall Schwimmbad
A5: geg | B5: Verdunstungswert ε | C5: 5 | D5: g/m3*h*mbar
B6: Fläche | C6: =Volumenstrom_Badebetrieb!C34 -> 5 | D6: m2
B7: Wasserdampfsättigungsdruck | C7: =Volumenstrom_Badebetrieb!C35 -> 47.547838 | D7: mbar
B8: Wasserdampfdruck | C8: =Volumenstrom_Badebetrieb!C36 -> 21.63 | D8: mbar
A10: ges | B10: Wasserdampfanfall | C10: =C5*C6*(C7-C8) -> 647.94596 | D10: g/h
A12: Wasserdampfanfall Whirlpool
A13: geg | B13: Verdunstungswert ε | C13: 4 | D13: g/m3*h*mbar
B14: Fläche | C14: 0 | D14: m2
B15: Wasserdampfsättigungsdruck | C15: 33.6 | D15: mbar
B16: Wasserdampfdruck | C16: 21.63 | D16: mbar
A18: ges | B18: Wasserdampfanfall | C18: =C13*C14*(C15-C16) -> 0 | D18: g/h
A21: Wasserdampf total | C21: =C18+C10 -> 647.94596 | D21: g/h
A23: Dichteermittlung Luft
A25: geg | B25: Normdichte | C25: 1.293 | D25: kg/m3
B26: Temp | C26: 31 | D26: °C
B27: Druck absolut | C27: 950 | D27: Pa
A29: ges | B29: Dichte | C29: =C25*(273.15/(273.15+C26))*(C27/1013.25) -> 1.0887268 | D29: kg/m3
A31: Volumenstrom über Wasserdampf
A33: geg | B33: Wasserdampfanfall | C33: =C21 -> 647.94596 | D33: g/h
B34: Feuchte Raum | C34: 14.2 | D34: g/kg
B35: Feuchte ZUL | C35: 9 | D35: g/kg
B36: Dichte Luft | C36: =C29 -> 1.0887268 | D36: kg/m3
A38: ges | B38: Volumenstrom über Dampfanfall | C38: =C33/(C36*C34-C35) -> 100.30247 | D38: m3/h

Sheet Min_Volumenstrom_für_Fenster
A1: Berechnungen Luftmenge Fenster
A3: Min Volumentrom Fenster
A5: geg | B5: Volumenstrom gegen Kondenz | C5: 125 | D5: m3/h*m
B6: Laufmeter Fenster | C6: 9.5 | D6: m
A8: ges | B8: Wasserdampfanfall | C8: =C5*C6 -> 1187.5 | D8: m3/h

Sheet Volumenstrom_über_Wärmeanfall
A1: Berechnung Wärmeanfall
A3: Transmissionsverlust
A5: geg | B5: spezifische Transmisssionsverlust | C5: 35 | D5: W/m2
B6: Fläche | C6: 105.5 | D6: m2
A8: ges | B8: Transmissionsverlust | C8: =C6*C5 -> 3692.5 | D8: W
A10: Anteil Lüftung
A12: geg | B12: Transmissionsverlust | C12: =C8 -> 3692.5 | D12: W
B13: Bruttofläche | C13: 45.5 | D13: m2
B15: Spez Transmissionsverlust | C15: =C12/C13 -> 81.153846 | D15: W/m2
B18: Spezifische Wärmeleistung FBH | C18: 70 | D18: W/m2
B19: Bruttofläche | C19: =C13 -> 45.5 | D19: m2
B20: Anteil FBH | C20: =C19*C18 -> 3185 | D20: W
B22: Transmissionsverlust | C22: =C12 -> 3692.5 | D22: W
B23: Transmissionsverlust Anteil FBH | C23: =C20 -> 3185 | D23: W
A24: ges | B24: Transmissionsverlust Anteil Lüftung | C24: =C22-C23 -> 507.5 | D24: W
A26: Dichteermittlung Luft
A28: geg | B28: Normdichte | C28: 1.293 | D28: kg/m3
B29: Temperatur | C29: 15 | D29: °C
B30: Druck absolut | C30: 950 | D30: Pa
A32: ges | B32: Dichte | C32: =C28*(273.15/(273.15+C29))*(C30/1013.25) -> 1.1491801 | D32: kg/m3
A34: Volumenstrom nach Wärmebedarf
A36: geg | B36: Transmissionsverlust Anteil Lüftung | C36: =C24 -> 507.5 | D36: W
B37: Spezifische Wärmekapazität | C37: 1006 | D37: W/kJ*K
B38: Temperaturfifferenz | C38: 1 | D38: K
B39: Dichte | C39: =C32 -> 1.1491801 | D39: kg/m3
A41: ges | B41: Volumenstrom nach Wärmelast | C41: =(C36*3600)/(C37*C38*C39) -> 1580.347 | D41: m3/h

Sheet Volumenstrom_nach_Personenbeleg
A1: Berechnung Personenbelegung
A3: Personenbelegung
A5: geg | B5: Spezifische Personenbelegung | C5: 5 | D5: m2/Pers
B6: Bruttofläche | C6: 60 | D6: m2
A8: ges | B8: Anzahl Personen | C8: =C6/C5 -> 12 | D8: Pers
A10: Minimaler Frischluftvolumenstrom
B12: Spezifische Frischluftrate | C12: 50 | D12: m3/h*Pers
B13: Anzahl Personen | C13: =C8 -> 12 | D13: Pers
B14: Volumenstrom | C14: =C13*C12 -> 600 | D14: m3/h

Sheet Zusammenfassung_Kosten
A1: Berechnung Energie / Kosten

Sheet Jahresenergiebedarf
A1: Berechnung Energie / Kosten
A3: Var 1 Luftenfeuchtung mit Kältemaschiene
A19: Var 2 Luftenfeuchtung durch Aussenluft-Umluft-Gemisch ohne WRG
A30: Var 3 Luftenfeuchtung durch Aussenluft-Umluft-Gemisch mit WRG
A43: Var 4 Luftenfeuchtung spezieller Monoblock für Schwimmbadentfeuchtung

Sheet Wartungs-,_Instanhaltungskosten
A1: Berechnung Energie / Kosten
A3: Var 1 Luftenfeuchtung mit Kältemaschiene
B5: Investition
A7: geg | B7: Spez. Investitionskosten | C7: 30 | D7: Fr./m3/h
B8: Volumenstrom | C8: =Volumenstrom_Badebetrieb!C67 -> 72.10237 | D8: m3/h
A10: ges | B10: Investitionskosten Monobloc | C10: =C8*C7 -> 2163.0711 | D10: Fr.
B11: Schätzung Investition Kanalnetz | C11: 10000 | D11: Fr.
B12: Investition Var 1 | C12: =C11+C10 -> 12163.071 | D12: Fr.
B15: Kapitalkosten
A17: geg | B17: Anuitätskosten | C17: 0.9
B18: Infestitionskosten | C18: =C12 -> 12163.071 | D18: Fr.
A20: ges | B20: Kaitalkosten
B23: Wartungskosten
A25: geg | B25: Prozentualer Anteil Wartung | C25: 2 | D25: %
A27: ges | B27: Wartung jährlich | C27: =C25*(C20/100) -> 0 | D27: Fr.
B30: Betriebskosten Kondesator
A32: geg | B32: Betriebsstunden Badebetrieb | C32: 728 | D32: h
B33: Betriebsstunden Ruhebetrieb | C33: 8008 | D33: h
B35: Energiekosten | C35: 0.2 | D35: Fr./kWh
B37: Kosten Strom Badebetrieb | C37: =C35*C32 -> 145.6 | D37: Fr.
B38: Kosten Strom Ruhebetrieb | C38: =C35*C33 -> 1601.6 | D38: Fr.
B40: Energiekosten Strom Total | C40: =C38+C37 -> 1747.2 | D40: Fr.
A43: Var 2 Luftenfeuchtung durch Aussenluft-Umluft-Gemisch ohne WRG
B45: Investition
A47: geg | B47: Spez. Investitionskosten | C47: 32 | D47: Fr./m3/h
B48: Volumenstrom | C48: =Volumenstrom_Badebetrieb!C67 -> 72.10237 | D48: m3/h
A50: ges | B50: Investitionskosten Monobloc | C50: =C48*C47 -> 2307.2759 | D50: Fr.
B51: Schätzung Infestition Kanalnetz | C51: 10000 | D51: Fr.
B52: Investition Var 2 | C52: =C51+C50 -> 12307.276 | D52: Fr.
A55: geg | B55: Prozentualer Anteil Wartung | C55: 2 | D55: %
A57: ges | B57: Wartung jährlich | C57: =C52*(C55/100) -> 246.14552 | D57: Fr.
A60: Dichteermittlung mittleren Luftteperatur
A62: geg | B62: Normdichte | C62: 1.293 | D62: kg/m3
B63: Temp | C63: 22 | D63: °C
B64: Druck | C64: 950 | D64: Pa
A66: ges | B66: Dichte | C66: =C62*(273.15/(273.15+C63))*(C64/1013.25) -> 1.1219253 | D66: kg/m3
B69: Betriebskosten Lufterhitzer
A71: geg | B71: Betriebsstunden Badebetrieb | C71: 728 | D71: h
B72: Betriebsstunden Ruhebetrieb | C72: 8008 | D72: h
B73: mittlere Jahrestemperatur | C73: 14 | D73: °C
...

Sheet Jahresgesamtkosten
A1: Berechnung Energie / Kosten
